<?xml version="1.0"?>
<robot name="end_effector">
 
   <material name="gray">
      <color rgba="0.4078 0.4078 0.4078 1"/>
   </material>

   <material name="white">
      <color rgba="1 1 1 1"/>
   </material>
 
   <link name="bot_scissor">
      <inertial>
         <origin rpy="0 0 0" xyz="0.0001 0.0004 0.0115" />
         <mass value="3.28858495027196E-05"/>
         <inertia ixx="5E-10" ixy="0" ixz="0" iyy="5E-10" iyz="0" izz="0" />
      </inertial>
 
      <visual>
         <origin xyz="0 0 0" rpy="3.1416 -1.5708 0"/>
         <geometry>
            <mesh filename="package://surgeon/model/meshes/bot_scissor.stl"/>
         </geometry>
         <material name="white"/>
      </visual>
 
      <collision>
         <geometry>
            <mesh filename="package://surgeon/model/meshes/bot_scissor.stl"/>
         </geometry>
      </collision>
   </link>
 
 
   <link name="top_scissor">
      <inertial>
         <origin rpy="0 0 0" xyz="-0.0001 -0.0007 0.0117" />
         <mass value="3.29063726784052E-05"/>
         <inertia ixx="5E-10" ixy="0" ixz="0" iyy="5E-10" iyz="0" izz="0" />
      </inertial>
 
      <visual>
         <origin xyz="0 0 0" rpy="3.1416 -1.5708 0"/>
         <geometry>
            <mesh filename="package://surgeon/model/meshes/top_scissor.stl"/>
         </geometry>
         <material name="white"/>
      </visual>
 
      <collision>
         <geometry>
            <mesh filename="package://surgeon/model/meshes/top_scissor.stl"/>
         </geometry>
      </collision>
   </link>
 
 
   <link name="head">
      <inertial>
         <origin rpy="0 0 0" xyz="0 0 0.0036" />
         <mass value="0.000145860751538374"/>
         <inertia ixx="2E-09" ixy="0" ixz="0" iyy="1.2E-09" iyz="0" izz="1.1E-09" />
      </inertial>
 
      <visual>
         <origin xyz="0 0 0" rpy="1.5708 1.5708 0"/>
         <geometry>
            <mesh filename="package://surgeon/model/meshes/head.stl"/>
         </geometry>
         <material name="white"/>
      </visual>
 
      <collision>
         <geometry>
            <mesh filename="package://surgeon/model/meshes/head.stl"/>
         </geometry>
      </collision>
   </link>
 
 
   <link name="base">
      <inertial>
         <origin rpy="0 0 0" xyz="0 0 -0.0065" />
         <mass value="0.000324283499010966"/>
         <inertia ixx="4.2E-09" ixy="0" ixz="0" iyy="4.6E-09" iyz="0" izz="2.5E-09" />
      </inertial>
 
      <visual>
         <origin xyz="0 0 0" rpy="0 1.5708 -1.5708"/>
         <geometry>
            <mesh filename="package://surgeon/model/meshes/base.stl"/>
         </geometry>
         <material name="white"/>
      </visual>
 
      <collision>
         <geometry>
            <mesh filename="package://surgeon/model/meshes/base.stl"/>
         </geometry>
      </collision>
   </link>
 
 
   <joint name="Rotational_1" type="continuous">
      <parent link="base"/>
      <child link="head"/>
      <origin xyz="0 0 0" rpy="0 0 0"/>
      <axis xyz="0 0 1"/>
   </joint>
 
 
   <joint name="Rotational_2" type="continuous">
      <parent link="head"/>
      <child link="bot_scissor"/>
      <origin xyz="0.75 -0.0875 0" rpy="1.5708 0 0"/>
      <axis xyz="0 0 1"/>
   </joint>
 
 
   <joint name="Rotational_3" type="continuous">
      <parent link="head"/>
      <child link="top_scissor"/>
      <origin xyz="0.75 0.0875 0" rpy="1.5708 0 0"/>
      <axis xyz="0 0 1"/>
   </joint>
 
 
</robot>
