<?xml version="1.0"?>
<robot name="end_effector">
 
   <material name="gray">
      <color rgba="0.4078 0.4078 0.4078 1"/>
   </material>

   <material name="white">
      <color rgba="1 1 1 1"/>
   </material>
 
   <link name = "world" />
 
   <link name="bot_scissor">
      <inertial>
         <origin rpy="0 0 0" xyz="0.0001 0.0004 0.0962" />
         <mass value="3.28858495027196E-05"/>
         <inertia ixx="5E-10" ixy="0" ixz="0" iyy="5E-10" iyz="0" izz="0" />
      </inertial>
 
      <visual>
         <origin xyz="0 0 0" rpy="3.1416 -1.5708 0"/>
         <geometry>
            <mesh filename="package://surgeon/model/meshes/bot_scissor.stl" scale="1 1 1"/>
         </geometry>
         <material name="white"/>
      </visual>
 
      <collision>
         <geometry>
            <mesh filename="package://surgeon/model/meshes/bot_scissor.stl" scale="1 1 1"/>
         </geometry>
      </collision>
   </link>
 
 
   <link name="top_scissor">
      <inertial>
         <origin rpy="0 0 0" xyz="-0.0001 -0.0007 0.0964" />
         <mass value="3.29063726784052E-05"/>
         <inertia ixx="5E-10" ixy="0" ixz="0" iyy="5E-10" iyz="0" izz="0" />
      </inertial>
 
      <visual>
         <origin xyz="0 0 0" rpy="3.1416 -1.5708 0"/>
         <geometry>
            <mesh filename="package://surgeon/model/meshes/top_scissor.stl" scale="1 1 1"/>
         </geometry>
         <material name="white"/>
      </visual>
 
      <collision>
         <geometry>
            <mesh filename="package://surgeon/model/meshes/top_scissor.stl" scale="1 1 1"/>
         </geometry>
      </collision>
   </link>
 
 
   <link name="head">
      <inertial>
         <origin rpy="0 0 0" xyz="0 0 0.0883" />
         <mass value="0.000145860751538374"/>
         <inertia ixx="2E-09" ixy="0" ixz="0" iyy="1.2E-09" iyz="0" izz="1.1E-09" />
      </inertial>
 
      <visual>
         <origin xyz="0 0 0" rpy="0 1.5708 0"/>
         <geometry>
            <mesh filename="package://surgeon/model/meshes/head.stl" scale="1 1 1"/>
         </geometry>
         <material name="white"/>
      </visual>
 
      <collision>
         <geometry>
            <mesh filename="package://surgeon/model/meshes/head.stl" scale="1 1 1"/>
         </geometry>
      </collision>
   </link>
 
 
   <link name="base">
      <inertial>
         <origin rpy="0 0 0" xyz="0 0 0.0782" />
         <mass value="0.000324283499010966"/>
         <inertia ixx="4.2E-09" ixy="0" ixz="0" iyy="4.6E-09" iyz="0" izz="2.5E-09" />
      </inertial>
 
      <visual>
         <origin xyz="0 0 0" rpy="0 1.5708 0"/>
         <geometry>
            <mesh filename="package://surgeon/model/meshes/base.stl" scale="1 1 1"/>
         </geometry>
         <material name="white"/>
      </visual>
 
      <collision>
         <geometry>
            <mesh filename="package://surgeon/model/meshes/base.stl" scale="1 1 1"/>
         </geometry>
      </collision>
   </link>
 
 
   <link name="tube">
      <inertial>
         <origin rpy="0 0 0" xyz="0 0 -0.0483" />
         <mass value="0.00765763209312479"/>
         <inertia ixx="3.99261E-05" ixy="0" ixz="0" iyy="3.99261E-05" iyz="0" izz="8.52E-08" />
      </inertial>
 
      <visual>
         <origin xyz="0 0 0" rpy="0 0 0"/>
         <geometry>
            <mesh filename="package://surgeon/model/meshes/tube.stl" scale="1 1 1"/>
         </geometry>
         <material name="white"/>
      </visual>
 
      <collision>
         <geometry>
            <mesh filename="package://surgeon/model/meshes/tube.stl" scale="1 1 1"/>
         </geometry>
      </collision>
   </link>
 
 
   <link name="ref">
      <inertial>
         <origin rpy="0 0 0" xyz="0 0 0" />
         <mass value="0.00123228317338585"/>
         <inertia ixx="9.33E-08" ixy="0" ixz="0" iyy="9.33E-08" iyz="0" izz="4.93E-08" />
      </inertial>
 
      <visual>
         <origin xyz="0 0 -1.2" rpy="0 0 0"/>
         <geometry>
            <mesh filename="package://surgeon/model/meshes/ref.stl" scale="1 1 1"/>
         </geometry>
         <material name="white"/>
      </visual>
 
      <collision>
         <geometry>
            <mesh filename="package://surgeon/model/meshes/ref.stl" scale="1 1 1"/>
         </geometry>
      </collision>
   </link>

   <joint name="Fixed_1" type="fixed">
      <parent link="world"/>
      <child link="ref"/>
      <origin xyz="-13.3 0 0" rpy="3.1416 -1.5708 0"/>
      <axis xyz="0 0 1"/>
   </joint>

   <joint name="Prismatic_1" type="prismatic">
      <limit effort="30" velocity="1.0" lower="0" upper="12.2"/> 
      <parent link="ref"/>
      <child link="tube"/>
      <origin xyz="0 0 -6.03" rpy="0 0 0"/>
      <axis xyz="0 0 1"/>
   </joint>

   <joint name="Fixed_2" type="fixed">
      <parent link="tube"/>
      <child link="base"/>
      <origin xyz="0 0 13.3" rpy="1.5708 0 0"/>
      <axis xyz="0 0 1"/>
   </joint>
 
 
   <joint name="Rotational_1" type="continuous">
      <parent link="base"/>
      <child link="head"/>
      <origin xyz="0 0 0" rpy="0 0 0"/>
      <axis xyz="0 0 1"/>
   </joint>
 
 
   <joint name="Rotational_2" type="continuous">
      <parent link="head"/>
      <child link="bot_scissor"/>
      <origin xyz="0.0875 0.75 0" rpy="1.5708 0 1.5708"/>
      <axis xyz="0 0 1"/>
   </joint>
 
 
   <joint name="Rotational_3" type="continuous">
      <parent link="head"/>
      <child link="top_scissor"/>
      <origin xyz="-0.0875 0.75 0" rpy="1.5708 0 1.5708"/>
      <axis xyz="0 0 1"/>
   </joint>

</robot>
